Workbook

Sheet 안내
A1: 분야–과정 연결 검수 시트
A3: 목적 | B3: 고객용 화면은 과정명 키워드로 과정을 9개 인사 분야에 자동 연결합니다. 이 연결이 맞는지 사람이 확인합니다.
A4: 대상 | B4: 확정 과정 212개(같은 과정명은 하나로 묶음). 출처: data/hr/output/recommendation/hr_recommendation_candidates.csv
A5: 입력할 칸 | B5: '검수' 시트의 노란 칸만 입력합니다. 회색 칸은 자동으로 채운 정보이니 고치지 마세요.
A6: 배정 | B6: '배정' 열에 적힌 팀원이 그 행을 검수합니다(팀원A~D가 순서대로 나눔). 필터로 내 행만 볼 수 있습니다.
A7: ① 인사·총무 관련 여부 | B7: 과정 자체가 인사·총무 업무에 관련 있는지: 관련 / 일부 관련 / 무관
A8: ② 자동 연결 분야 판정 | B8: '자동 연결 분야'가 맞는지: 맞음 / 일부 틀림(일부만 맞음) / 틀림. 분야가 '(없음)'인데 맞는 분야가 있으면 '틀림'으로 고르고 ③에 적습니다.
A9: ③ 추가할 분야 / ④ 뺄 분야 | B9: '분야 기준' 시트의 분야 이름을 그대로 적습니다. 여러 개면 쉼표로 구분합니다. ②가 틀림·일부 틀림인데 ③·④가 비어 있으면 ②가 빨간 글씨로 표시됩니다.
A10: 판단 기준 | B10: 과정명만 보고 애매하면 '링크'를 열어 과정 소개를 확인합니다. 그래도 애매하면 메모에 이유를 적습니다.
A11: 교차검수 | B11: '교차검수' 시트의 20개 과정은 1차 배정과 다른 팀원이 한 번 더 판정합니다(팀원당 5개). '교차 배정'에 적힌 팀원이 '검수' 시트의 판정을 보지 말고 독립적으로 입력해 주세요. 두 판정의 일치율로 판정 기준이 팀원 간에 같은지 확인합니다.
A12: 결과 확인 | B12: '요약' 시트에서 진행률, 판정 분포, 분야별 일치율, 교차검수 일치율과 카파 계수가 자동으로 계산됩니다.
A13: 주의 | B13: 고용24 과정은 2025년 회차 기준이라 링크의 회차가 끝났을 수 있습니다. 검수는 과정 내용 기준으로 합니다.
A15: 입력 예시 (검수 시트 형식)
A16: 과정명 | B16: 채용에서 퇴직까지 인사노무관리 핵심실무
A17: 자동 연결 분야 | B17: 인재채용, 노사관계·노무
A18: ① 관련 여부 | B18: 관련
A19: ② 판정 | B19: 일부 틀림
A20: ③ 추가할 분야 | B20: 보상·급여·복리후생
A21: ④ 뺄 분야
A22: 메모 | B22: 목차에 급여·퇴직금 계산 포함(링크 확인)

Sheet 검수
A1: 번호 | B1: 배정 | C1: 과정ID | D1: 과정명 | E1: 기관 | F1: 플랫폼 | G1: 링크 | H1: 기존 역량(키워드 분류) | I1: 자동 연결 분야 | J1: 연결 근거 키워드 | K1: ① 인사·총무 관련 여부 | L1: ② 자동 연결 분야 판정 | M1: ③ 추가할 분야 | N1: ④ 뺄 분야 | O1: 메모 | P1: 검수자 | Q1: 검수일
A2: 1 | B2: 팀원A | C2: PUB_ACG20243000973001_324 | D2: 알베르토와 함께하는 글로벌 비즈니스 매너 | E2: 에듀퓨어 | F2: 고용24 국민내일배움카드 | G2: 열기 | H2: 비즈니스 매너 및 커뮤니케이션 | I2: (없음)
A3: 2 | B3: 팀원B | C3: PUB_ACG20243001004189_245 | D3: 기획력, 어떻게 끌리는 플랜을 세울 것인가? | E3: 에듀퓨어 | F3: 고용24 국민내일배움카드 | G3: 열기 | H3: 문서작성 및 기획 | I3: (없음)
A4: 3 | B4: 팀원C | C4: PUB_ABA20243001045717_58 | D4: 핵심만 콕! 회사의 가치를 높여주는 홍보전략 | E4: 에듀퓨어 | F4: 고용24 사업주훈련 | G4: 열기 | H4: 문서작성 및 기획 | I4: (없음)
A5: 4 | B5: 팀원D | C5: PUB_ABA20243001011994_6 | D5: 품격 있게 승리하는 직장인의 말하기 기술 | E5: 고려아카데미(원격) | F5: 고용24 사업주훈련 | G5: 열기 | H5: 문서작성 및 기획 | I5: (없음)
A6: 5 | B6: 팀원A | C6: PUB_ABA20243001012836_203 | D6: 달콤한 업무꿀팁! 평범한 당신이 비범하게 일하는 기술 | E6: 에듀퓨어 | F6: 고용24 사업주훈련 | G6: 열기 | H6: 문서작성 및 기획 | I6: (없음)
A7: 6 | B7: 팀원B | C7: PUB_ABA20243000994834_261 | D7: 핵심만 콕! 비즈니스 글쓰기와 보고서 작성 노하우 | E7: 에듀퓨어 외 2곳 | F7: 고용24 사업주훈련 | G7: 열기 | H7: 문서작성 및 기획 | I7: (없음)
A8: 7 | B8: 팀원C | C8: PUB_ABA20243001049771_3 | D8: 빨리 배워 바로 쓰는 엑셀 2013 | E8: 휴넷 | F8: 고용24 사업주훈련 | G8: 열기 | H8: 문서작성 및 기획 | I8: (없음)
A9: 8 | B9: 팀원D | C9: PUB_ABA20243001011985_5 | D9: 직장 생존력 UP! 데이터 마인드셋 장착하기 | E9: 고려아카데미(원격) | F9: 고용24 사업주훈련 | G9: 열기 | H9: 문서작성 및 기획 | I9: (없음)
A10: 9 | B10: 팀원A | C10: PUB_ABA20243000972962_324 | D10: 한달 공부로 실무에 바로 통하는 데이터분석 | E10: 에듀퓨어 | F10: 고용24 사업주훈련 | G10: 열기 | H10: 문서작성 및 기획 | I10: (없음)
A11: 10 | B11: 팀원B | C11: PUB_ACG20243001038036_84 | D11: 전략적 조직운영을 위한 인사관리 실무 | E11: 에듀퓨어 외 3곳 | F11: 고용24 국민내일배움카드 | G11: 열기 | H11: 인력채용 | I11: (없음)
A12: 11 | B12: 팀원C | C12: PUB_ACG20243001023998_11 | D12: 총무기획과 총무자산관리 | E12: 이룸캠퍼스 외 3곳 | F12: 고용24 국민내일배움카드 | G12: 열기 | H12: 비품 및 자산관리 | I12: (없음)
A13: 12 | B13: 팀원D | C13: PUB_ACG20243001054796_4 | D13: 채용에서 퇴직까지 인사노무관리 핵심실무 | E13: 케이지에듀원 원격평생교육원 외 4곳 | F13: 고용24 국민내일배움카드 | G13: 열기 | H13: 근로관계 법률 준수 | I13: 인재채용, 노사관계·노무 | J13: 노무, 채용
A14: 13 | B14: 팀원A | C14: PUB_ACG20243001052023_28 | D14: NEW 업무에서 활용가능한 실전 근로기준법 | E14: 에듀퓨어 외 1곳 | F14: 고용24 국민내일배움카드 | G14: 열기 | H14: 근로관계 법률 준수 | I14: 노사관계·노무 | J14: 근로기준법
A15: 14 | B15: 팀원B | C15: PUB_ACG20243001036448_16 | D15: 실무사례로 알아보는 근로기준법 | E15: 중앙법률원격평생교육원 | F15: 고용24 국민내일배움카드 | G15: 열기 | H15: 근로관계 법률 준수 | I15: 노사관계·노무 | J15: 근로기준법
A16: 15 | B16: 팀원C | C16: PUB_ACG20243001004851_141 | D16: 인사평가체계 구축 및 운영 방법 | E16: 케이스원격평생교육원 외 5곳 | F16: 고용24 국민내일배움카드 | G16: 열기 | H16: 인사평가 및 보상 | I16: 성과평가·목표관리 | J16: 인사평가, 평가체계
A17: 16 | B17: 팀원D | C17: PUB_AIG20220000383835_15 | D17: 채용에서 퇴직까지 인사관리 실무 | E17: 더존평생교육원 | F17: 고용24 사업주훈련 | G17: 열기 | H17: 인력채용 | I17: 인재채용 | J17: 채용
A18: 17 | B18: 팀원A | C18: PUB_AIG20240000492923_1 | D18: 채용에서 퇴직까지 인사노무임금관리실무 | E18: 씨에프오아카데미평생교육원 | F18: 고용24 사업주훈련 | G18: 열기 | H18: 근로관계 법률 준수 | I18: 인재채용, 보상·급여·복리후생, 노사관계·노무 | J18: 노무, 임금, 채용
A19: 18 | B19: 팀원B | C19: PUB_AIG20240000475110_1 | D19: 2일 완성, 노동법 마스터 | E19: 중앙경제HR교육원 | F19: 고용24 사업주훈련 | G19: 열기 | H19: 근로관계 법률 준수 | I19: 노사관계·노무 | J19: 노동법
A20: 19 | B20: 팀원C | C20: PUB_AIG20240000472845_1 | D20: 실전! 인사평가제도 기획 방법론 | E20: HR에듀센터 인사드림 | F20: 고용24 사업주훈련 | G20: 열기 | H20: 인사평가 및 보상 | I20: 성과평가·목표관리 | J20: 인사평가, 평가제도
A21: 20 | B21: 팀원D | C21: PUB_ABA20243001036526_9 | D21: 급변하는 비즈니스 환경의 총무관리 역할 | E21: 한국직장인교육센터평생교육원 | F21: 고용24 사업주훈련 | G21: 열기 | H21: 문서작성 및 기획 | I21: (없음)
A22: 21 | B22: 팀원A | C22: SQL_FASTCAMPUS_210569 | D22: 문서의 신이 알려주는 보고서의 법칙 : 비즈니스 글쓰기의 모든 것 | E22: 패스트캠퍼스 | F22: 패스트캠퍼스 | G22: 열기 | H22: 문서작성 및 기획 | I22: (없음)
A23: 22 | B23: 팀원B | C23: SQL_FASTCAMPUS_243273 | D23: 세계 3대 컨설팅펌 출신 김영롱에게 배우는 1조 가치 보고서 작성법 | E23: 패스트캠퍼스 | F23: 패스트캠퍼스 | G23: 열기 | H23: 문서작성 및 기획 | I23: (없음)
A24: 23 | B24: 팀원C | C24: SQL_FASTCAMPUS_249157 | D24: 맥킨지·제일기획 출신 김재성의 연봉을 올리는 보고서 & 프레젠테이션 공식 | E24: 패스트캠퍼스 | F24: 패스트캠퍼스 | G24: 열기 | H24: 문서작성 및 기획 | I24: (없음)
A25: 24 | B25: 팀원D | C25: SQL_FASTCAMPUS_252453 | D25: 평범한 대학생에서 억대 연봉 작가로! 500개 예제로 끝내는 이모티콘 족집게 트레이닝 | E25: 패스트캠퍼스 | F25: 패스트캠퍼스 | G25: 열기 | H25: 인사평가 및 보상 | I25: (없음)
A26: 25 | B26: 팀원A | C26: SQL_FASTCAMPUS_261333 | D26: 콜롬버스의 탐색 - 글로벌 시장 트렌드 분석 보고서 작성 | E26: 패스트캠퍼스 | F26: 패스트캠퍼스 | G26: 열기 | H26: 문서작성 및 기획 | I26: (없음)
A27: 26 | B27: 팀원B | C27: SQL_GSEEK_3217 | D27: [창업공통]필수 근로기준법과 인사서식 | E27: 경기도평생학습포털(GSEEK) | F27: 경기도 GSEEK | G27: 열기 | H27: 근로관계 법률 준수 | I27: 노사관계·노무 | J27: 근로기준법
A28: 27 | B28: 팀원C | C28: SQL_GSEEK_4378 | D28: 사용자에게 꼭 필요한 사이다 노동법 | E28: 경기도평생학습포털(GSEEK) | F28: 경기도 GSEEK | G28: 열기 | H28: 근로관계 법률 준수 | I28: 노사관계·노무 | J28: 노동법
A29: 28 | B29: 팀원D | C29: SQL_GSEEK_5045 | D29: 소규모 사업장 랜선노동법 | E29: 경기도평생학습포털(GSEEK) | F29: 경기도 GSEEK | G29: 열기 | H29: 인력채용 | I29: 노사관계·노무 | J29: 노동법
A30: 29 | B30: 팀원A | C30: SQL_GSEEK_5793 | D30: 소규모사업주가 알아야 할 노동법 상식 | E30: 경기도평생학습포털(GSEEK) | F30: 경기도 GSEEK | G30: 열기 | H30: 인력채용 | I30: 노사관계·노무 | J30: 노동법
A31: 30 | B31: 팀원B | C31: SQL_GSEEK_5794 | D31: 알바가 꼭 알아야 할 기초노동법 | E31: 경기도평생학습포털(GSEEK) | F31: 경기도 GSEEK | G31: 열기 | H31: 근로관계 법률 준수 | I31: 노사관계·노무 | J31: 노동법
A32: 31 | B32: 팀원C | C32: SQL_GSEEK_7414 | D32: (왕초보)컴퓨터로 문서작성 도전 | E32: 경기도평생학습포털(GSEEK) | F32: 경기도 GSEEK | G32: 열기 | H32: 문서작성 및 기획 | I32: (없음)
A33: 32 | B33: 팀원D | C33: SQL_GSEEK_8297 | D33: [오늘부터 정시퇴근] 엑셀 실무 테크닉 - 일잘러의 보고서 작성편 | E33: 경기도평생학습포털(GSEEK) 외 1곳 | F33: 경기도 GSEEK | G33: 열기 | H33: 문서작성 및 기획 | I33: (없음)
A34: 33 | B34: 팀원A | C34: SQL_GSEEK_51667 | D34: 따라만 하면 OK! 말이 되는 보고서 작성 원칙 | E34: 경기도평생학습포털(GSEEK) | F34: 경기도 GSEEK | G34: 열기 | H34: 문서작성 및 기획 | I34: (없음)
A35: 34 | B35: 팀원B | C35: SQL_GSEEK_51955 | D35: [레전드 스킬] 어쩐지 끌리는 사람의 비즈니스 매너 | E35: 경기도평생학습포털(GSEEK) 외 1곳 | F35: 경기도 GSEEK | G35: 열기 | H35: 비즈니스 매너 및 커뮤니케이션 | I35: (없음)
A36: 35 | B36: 팀원C | C36: SQL_GSEEK_52754 | D36: [칼퇴를 부르는 치트키_보고서편] 핵심만 콕! 비즈니스 문서작성의 핵심과 실무 스킬 | E36: 경기도평생학습포털(GSEEK) | F36: 경기도 GSEEK | G36: 열기 | H36: 문서작성 및 기획 | I36: (없음)
A37: 36 | B37: 팀원D | C37: SQL_GSEEK_55196 | D37: 인사담당자에게 묻는다! 면접 합격의 비밀 | E37: 경기도평생학습포털(GSEEK) | F37: 경기도 GSEEK | G37: 열기 | H37: 인력채용 | I37: 인재채용 | J37: 면접
A38: 37 | B38: 팀원A | C38: SQL_GSEEK_55218 | D38: 경기도 스파크 노동법 | E38: 경기도평생학습포털(GSEEK) | F38: 경기도 GSEEK | G38: 열기 | H38: 근로관계 법률 준수 | I38: 노사관계·노무 | J38: 노동법
A39: 38 | B39: 팀원B | C39: SQL_GSEEK_56932 | D39: (리프레시) 핵심만 콕! 신입사원 온보딩 | E39: 경기도평생학습포털(GSEEK) | F39: 경기도 GSEEK | G39: 열기 | H39: 인력채용 | I39: 온보딩·직원경험 | J39: 신입사원, 온보딩
A40: 39 | B40: 팀원C | C40: SQL_GSEEK_57049 | D40: HR, AI가 트렌드다 : 채용부터 퇴사까지 | E40: 경기도평생학습포털(GSEEK) 외 1곳 | F40: 경기도 GSEEK | G40: 열기 | H40: 인력채용 | I40: 인재채용 | J40: 채용
...

Sheet 교차검수
A1: 번호 | B1: 교차 배정 | C1: 과정ID | D1: 과정명 | E1: 기관 | F1: 링크 | G1: 자동 연결 분야 | H1: 연결 근거 키워드 | I1: ① 인사·총무 관련 여부 | J1: ② 자동 연결 분야 판정 | K1: ③ 추가할 분야 | L1: ④ 뺄 분야 | M1: 메모 | N1: 검수자 | O1: 검수일 | P1: 1차 배정 | Q1: 1차 ① 관련 여부 | R1: 1차 ② 판정 | S1: ② 판정 일치 | T1: ① 관련 여부 일치
A2: 1 | B2: 팀원B | C2: PUB_ACG20243000973001_324 | D2: 알베르토와 함께하는 글로벌 비즈니스 매너 | E2: 에듀퓨어 | F2: 열기 | G2: (없음) | P2: 팀원A | Q2: =IFERROR(IF(INDEX(검수!$K$2:$K$184,MATCH($C2,검수!$C$2:$C$184,0))="","",INDEX(검수!$K$2:$K$184,MATCH($C2,검수!$C$2:$C$184,0))),"") | R2: =IFERROR(IF(INDEX(검수!$L$2:$L$184,MATCH($C2,검수!$C$2:$C$184,0))="","",INDEX(검수!$L$2:$L$184,MATCH($C2,검수!$C$2:$C$184,0))),"") | S2: =IF(OR(R2="",J2=""),"",IF(R2=J2,"일치","불일치")) | T2: =IF(OR(Q2="",I2=""),"",IF(Q2=I2,"일치","불일치"))
A3: 2 | B3: 팀원A | C3: PUB_ACG20243001054796_4 | D3: 채용에서 퇴직까지 인사노무관리 핵심실무 | E3: 케이지에듀원 원격평생교육원 외 4곳 | F3: 열기 | G3: 인재채용, 노사관계·노무 | H3: 노무, 채용 | P3: 팀원D | Q3: =IFERROR(IF(INDEX(검수!$K$2:$K$184,MATCH($C3,검수!$C$2:$C$184,0))="","",INDEX(검수!$K$2:$K$184,MATCH($C3,검수!$C$2:$C$184,0))),"") | R3: =IFERROR(IF(INDEX(검수!$L$2:$L$184,MATCH($C3,검수!$C$2:$C$184,0))="","",INDEX(검수!$L$2:$L$184,MATCH($C3,검수!$C$2:$C$184,0))),"") | S3: =IF(OR(R3="",J3=""),"",IF(R3=J3,"일치","불일치")) | T3: =IF(OR(Q3="",I3=""),"",IF(Q3=I3,"일치","불일치"))
A4: 3 | B4: 팀원C | C4: PUB_ACG20243001052023_28 | D4: NEW 업무에서 활용가능한 실전 근로기준법 | E4: 에듀퓨어 외 1곳 | F4: 열기 | G4: 노사관계·노무 | H4: 근로기준법 | P4: 팀원A | Q4: =IFERROR(IF(INDEX(검수!$K$2:$K$184,MATCH($C4,검수!$C$2:$C$184,0))="","",INDEX(검수!$K$2:$K$184,MATCH($C4,검수!$C$2:$C$184,0))),"") | R4: =IFERROR(IF(INDEX(검수!$L$2:$L$184,MATCH($C4,검수!$C$2:$C$184,0))="","",INDEX(검수!$L$2:$L$184,MATCH($C4,검수!$C$2:$C$184,0))),"") | S4: =IF(OR(R4="",J4=""),"",IF(R4=J4,"일치","불일치")) | T4: =IF(OR(Q4="",I4=""),"",IF(Q4=I4,"일치","불일치"))
A5: 4 | B5: 팀원D | C5: PUB_ACG20243001004851_141 | D5: 인사평가체계 구축 및 운영 방법 | E5: 케이스원격평생교육원 외 5곳 | F5: 열기 | G5: 성과평가·목표관리 | H5: 인사평가, 평가체계 | P5: 팀원C | Q5: =IFERROR(IF(INDEX(검수!$K$2:$K$184,MATCH($C5,검수!$C$2:$C$184,0))="","",INDEX(검수!$K$2:$K$184,MATCH($C5,검수!$C$2:$C$184,0))),"") | R5: =IFERROR(IF(INDEX(검수!$L$2:$L$184,MATCH($C5,검수!$C$2:$C$184,0))="","",INDEX(검수!$L$2:$L$184,MATCH($C5,검수!$C$2:$C$184,0))),"") | S5: =IF(OR(R5="",J5=""),"",IF(R5=J5,"일치","불일치")) | T5: =IF(OR(Q5="",I5=""),"",IF(Q5=I5,"일치","불일치"))
A6: 5 | B6: 팀원B | C6: SQL_GSEEK_5793 | D6: 소규모사업주가 알아야 할 노동법 상식 | E6: 경기도평생학습포털(GSEEK) | F6: 열기 | G6: 노사관계·노무 | H6: 노동법 | P6: 팀원A | Q6: =IFERROR(IF(INDEX(검수!$K$2:$K$184,MATCH($C6,검수!$C$2:$C$184,0))="","",INDEX(검수!$K$2:$K$184,MATCH($C6,검수!$C$2:$C$184,0))),"") | R6: =IFERROR(IF(INDEX(검수!$L$2:$L$184,MATCH($C6,검수!$C$2:$C$184,0))="","",INDEX(검수!$L$2:$L$184,MATCH($C6,검수!$C$2:$C$184,0))),"") | S6: =IF(OR(R6="",J6=""),"",IF(R6=J6,"일치","불일치")) | T6: =IF(OR(Q6="",I6=""),"",IF(Q6=I6,"일치","불일치"))
A7: 6 | B7: 팀원A | C7: SQL_GSEEK_52754 | D7: [칼퇴를 부르는 치트키_보고서편] 핵심만 콕! 비즈니스 문서작성의 핵심과 실무 스킬 | E7: 경기도평생학습포털(GSEEK) | F7: 열기 | G7: (없음) | P7: 팀원C | Q7: =IFERROR(IF(INDEX(검수!$K$2:$K$184,MATCH($C7,검수!$C$2:$C$184,0))="","",INDEX(검수!$K$2:$K$184,MATCH($C7,검수!$C$2:$C$184,0))),"") | R7: =IFERROR(IF(INDEX(검수!$L$2:$L$184,MATCH($C7,검수!$C$2:$C$184,0))="","",INDEX(검수!$L$2:$L$184,MATCH($C7,검수!$C$2:$C$184,0))),"") | S7: =IF(OR(R7="",J7=""),"",IF(R7=J7,"일치","불일치")) | T7: =IF(OR(Q7="",I7=""),"",IF(Q7=I7,"일치","불일치"))
A8: 7 | B8: 팀원C | C8: SQL_GSEEK_56932 | D8: (리프레시) 핵심만 콕! 신입사원 온보딩 | E8: 경기도평생학습포털(GSEEK) | F8: 열기 | G8: 온보딩·직원경험 | H8: 신입사원, 온보딩 | P8: 팀원B | Q8: =IFERROR(IF(INDEX(검수!$K$2:$K$184,MATCH($C8,검수!$C$2:$C$184,0))="","",INDEX(검수!$K$2:$K$184,MATCH($C8,검수!$C$2:$C$184,0))),"") | R8: =IFERROR(IF(INDEX(검수!$L$2:$L$184,MATCH($C8,검수!$C$2:$C$184,0))="","",INDEX(검수!$L$2:$L$184,MATCH($C8,검수!$C$2:$C$184,0))),"") | S8: =IF(OR(R8="",J8=""),"",IF(R8=J8,"일치","불일치")) | T8: =IF(OR(Q8="",I8=""),"",IF(Q8=I8,"일치","불일치"))
A9: 8 | B9: 팀원D | C9: SQL_HUNET_Y00337189 | D9: [온보딩저니] 경력사원 과정 | E9: 휴넷 | F9: 열기 | G9: 온보딩·직원경험 | H9: 온보딩 | P9: 팀원A | Q9: =IFERROR(IF(INDEX(검수!$K$2:$K$184,MATCH($C9,검수!$C$2:$C$184,0))="","",INDEX(검수!$K$2:$K$184,MATCH($C9,검수!$C$2:$C$184,0))),"") | R9: =IFERROR(IF(INDEX(검수!$L$2:$L$184,MATCH($C9,검수!$C$2:$C$184,0))="","",INDEX(검수!$L$2:$L$184,MATCH($C9,검수!$C$2:$C$184,0))),"") | S9: =IF(OR(R9="",J9=""),"",IF(R9=J9,"일치","불일치")) | T9: =IF(OR(Q9="",I9=""),"",IF(Q9=I9,"일치","불일치"))
A10: 9 | B10: 팀원B | C10: SQL_HUNET_Y00319690 | D10: 평가에서 성과관리로, 프레임을 전환하라! | E10: 휴넷 | F10: 열기 | G10: 성과평가·목표관리 | H10: 성과관리 | P10: 팀원A | Q10: =IFERROR(IF(INDEX(검수!$K$2:$K$184,MATCH($C10,검수!$C$2:$C$184,0))="","",INDEX(검수!$K$2:$K$184,MATCH($C10,검수!$C$2:$C$184,0))),"") | R10: =IFERROR(IF(INDEX(검수!$L$2:$L$184,MATCH($C10,검수!$C$2:$C$184,0))="","",INDEX(검수!$L$2:$L$184,MATCH($C10,검수!$C$2:$C$184,0))),"") | S10: =IF(OR(R10="",J10=""),"",IF(R10=J10,"일치","불일치")) | T10: =IF(OR(Q10="",I10=""),"",IF(Q10=I10,"일치","불일치"))
A11: 10 | B11: 팀원A | C11: SQL_HUNET_Y00317658 | D11: 채용을 디자인하라, 기업에 FIT한 인재 확보 전략 | E11: 휴넷 | F11: 열기 | G11: 인재채용 | H11: 채용 | P11: 팀원B | Q11: =IFERROR(IF(INDEX(검수!$K$2:$K$184,MATCH($C11,검수!$C$2:$C$184,0))="","",INDEX(검수!$K$2:$K$184,MATCH($C11,검수!$C$2:$C$184,0))),"") | R11: =IFERROR(IF(INDEX(검수!$L$2:$L$184,MATCH($C11,검수!$C$2:$C$184,0))="","",INDEX(검수!$L$2:$L$184,MATCH($C11,검수!$C$2:$C$184,0))),"") | S11: =IF(OR(R11="",J11=""),"",IF(R11=J11,"일치","불일치")) | T11: =IF(OR(Q11="",I11=""),"",IF(Q11=I11,"일치","불일치"))
A12: 11 | B12: 팀원C | C12: SQL_HUNET_Y00260034 | D12: SSS급 확보를 위한 면접관 교육 | E12: 휴넷 | F12: 열기 | G12: 인재채용 | H12: 면접 | P12: 팀원D | Q12: =IFERROR(IF(INDEX(검수!$K$2:$K$184,MATCH($C12,검수!$C$2:$C$184,0))="","",INDEX(검수!$K$2:$K$184,MATCH($C12,검수!$C$2:$C$184,0))),"") | R12: =IFERROR(IF(INDEX(검수!$L$2:$L$184,MATCH($C12,검수!$C$2:$C$184,0))="","",INDEX(검수!$L$2:$L$184,MATCH($C12,검수!$C$2:$C$184,0))),"") | S12: =IF(OR(R12="",J12=""),"",IF(R12=J12,"일치","불일치")) | T12: =IF(OR(Q12="",I12=""),"",IF(Q12=I12,"일치","불일치"))
A13: 12 | B13: 팀원D | C13: SQL_HUNET_Y00030777 | D13: 전략적 인재 육성을 위한 HRD 에센스 | E13: 휴넷 | F13: 열기 | G13: 인재육성·사내교육 | H13: hrd | P13: 팀원C | Q13: =IFERROR(IF(INDEX(검수!$K$2:$K$184,MATCH($C13,검수!$C$2:$C$184,0))="","",INDEX(검수!$K$2:$K$184,MATCH($C13,검수!$C$2:$C$184,0))),"") | R13: =IFERROR(IF(INDEX(검수!$L$2:$L$184,MATCH($C13,검수!$C$2:$C$184,0))="","",INDEX(검수!$L$2:$L$184,MATCH($C13,검수!$C$2:$C$184,0))),"") | S13: =IF(OR(R13="",J13=""),"",IF(R13=J13,"일치","불일치")) | T13: =IF(OR(Q13="",I13=""),"",IF(Q13=I13,"일치","불일치"))
A14: 13 | B14: 팀원A | C14: SQL_KMA_111663 | D14: [여의도] 수시 경력입사자 온보딩 | E14: 한국능률협회 | F14: 열기 | G14: 온보딩·직원경험 | H14: 온보딩 | P14: 팀원B | Q14: =IFERROR(IF(INDEX(검수!$K$2:$K$184,MATCH($C14,검수!$C$2:$C$184,0))="","",INDEX(검수!$K$2:$K$184,MATCH($C14,검수!$C$2:$C$184,0))),"") | R14: =IFERROR(IF(INDEX(검수!$L$2:$L$184,MATCH($C14,검수!$C$2:$C$184,0))="","",INDEX(검수!$L$2:$L$184,MATCH($C14,검수!$C$2:$C$184,0))),"") | S14: =IF(OR(R14="",J14=""),"",IF(R14=J14,"일치","불일치")) | T14: =IF(OR(Q14="",I14=""),"",IF(Q14=I14,"일치","불일치"))
A15: 14 | B15: 팀원B | C15: SQL_KMA_111186 | D15: [여의도] HRD 전략과 교육체계 수립 | E15: 한국능률협회 | F15: 열기 | G15: 인재육성·사내교육 | H15: hrd | P15: 팀원D | Q15: =IFERROR(IF(INDEX(검수!$K$2:$K$184,MATCH($C15,검수!$C$2:$C$184,0))="","",INDEX(검수!$K$2:$K$184,MATCH($C15,검수!$C$2:$C$184,0))),"") | R15: =IFERROR(IF(INDEX(검수!$L$2:$L$184,MATCH($C15,검수!$C$2:$C$184,0))="","",INDEX(검수!$L$2:$L$184,MATCH($C15,검수!$C$2:$C$184,0))),"") | S15: =IF(OR(R15="",J15=""),"",IF(R15=J15,"일치","불일치")) | T15: =IF(OR(Q15="",I15=""),"",IF(Q15=I15,"일치","불일치"))
A16: 15 | B16: 팀원C | C16: SQL_KMA_111450 | D16: [여의도] 안정적인 노사관계를 위한 노동법 및 노사협의회 운영 실무 | E16: 한국능률협회 | F16: 열기 | G16: 노사관계·노무 | H16: 노동법, 노사 | P16: 팀원B | Q16: =IFERROR(IF(INDEX(검수!$K$2:$K$184,MATCH($C16,검수!$C$2:$C$184,0))="","",INDEX(검수!$K$2:$K$184,MATCH($C16,검수!$C$2:$C$184,0))),"") | R16: =IFERROR(IF(INDEX(검수!$L$2:$L$184,MATCH($C16,검수!$C$2:$C$184,0))="","",INDEX(검수!$L$2:$L$184,MATCH($C16,검수!$C$2:$C$184,0))),"") | S16: =IF(OR(R16="",J16=""),"",IF(R16=J16,"일치","불일치")) | T16: =IF(OR(Q16="",I16=""),"",IF(Q16=I16,"일치","불일치"))
A17: 16 | B17: 팀원D | C17: SQL_KMA_111205 | D17: [강남] 성과 향상을 위한 인사평가(성과평가, 다면평가) 면담 Skill | E17: 한국능률협회 | F17: 열기 | G17: 성과평가·목표관리 | H17: 성과평가, 인사평가 | P17: 팀원B | Q17: =IFERROR(IF(INDEX(검수!$K$2:$K$184,MATCH($C17,검수!$C$2:$C$184,0))="","",INDEX(검수!$K$2:$K$184,MATCH($C17,검수!$C$2:$C$184,0))),"") | R17: =IFERROR(IF(INDEX(검수!$L$2:$L$184,MATCH($C17,검수!$C$2:$C$184,0))="","",INDEX(검수!$L$2:$L$184,MATCH($C17,검수!$C$2:$C$184,0))),"") | S17: =IF(OR(R17="",J17=""),"",IF(R17=J17,"일치","불일치")) | T17: =IF(OR(Q17="",I17=""),"",IF(Q17=I17,"일치","불일치"))
A18: 17 | B18: 팀원A | C18: SQL_KPC_49312 | D18: 2026년 KPC HRD 트렌드 세미나(무료) | E18: 한국생산성본부 | F18: 열기 | G18: 인재육성·사내교육 | H18: hrd | P18: 팀원D | Q18: =IFERROR(IF(INDEX(검수!$K$2:$K$184,MATCH($C18,검수!$C$2:$C$184,0))="","",INDEX(검수!$K$2:$K$184,MATCH($C18,검수!$C$2:$C$184,0))),"") | R18: =IFERROR(IF(INDEX(검수!$L$2:$L$184,MATCH($C18,검수!$C$2:$C$184,0))="","",INDEX(검수!$L$2:$L$184,MATCH($C18,검수!$C$2:$C$184,0))),"") | S18: =IF(OR(R18="",J18=""),"",IF(R18=J18,"일치","불일치")) | T18: =IF(OR(Q18="",I18=""),"",IF(Q18=I18,"일치","불일치"))
A19: 18 | B19: 팀원B | C19: SQL_KPC_47022 | D19: [DX&AI] 평가보상 설계 실무(밀코비치 기반) | E19: 한국생산성본부 | F19: 열기 | G19: 보상·급여·복리후생 | H19: 보상 | P19: 팀원D | Q19: =IFERROR(IF(INDEX(검수!$K$2:$K$184,MATCH($C19,검수!$C$2:$C$184,0))="","",INDEX(검수!$K$2:$K$184,MATCH($C19,검수!$C$2:$C$184,0))),"") | R19: =IFERROR(IF(INDEX(검수!$L$2:$L$184,MATCH($C19,검수!$C$2:$C$184,0))="","",INDEX(검수!$L$2:$L$184,MATCH($C19,검수!$C$2:$C$184,0))),"") | S19: =IF(OR(R19="",J19=""),"",IF(R19=J19,"일치","불일치")) | T19: =IF(OR(Q19="",I19=""),"",IF(Q19=I19,"일치","불일치"))
... A21: 20 | B21: 팀원D | C21: SQL_KPC_46993 | D21: [인력계획부터 육성까지] 인사기획실무 | E21: 한국생산성본부 | F21: 열기 | G21: 인사전략·인력기획 | H21: 인력계획, 인사기획 | P21: 팀원C | Q21: =IFERROR(IF(INDEX(검수!$K$2:$K$184,MATCH($C21,검수!$C$2:$C$184,0))="","",INDEX(검수!$K$2:$K$184,MATCH($C21,검수!$C$2:$C$184,0))),"") | R21: =IFERROR(IF(INDEX(검수!$L$2:$L$184,MATCH($C21,검수!$C$2:$C$184,0))="","",INDEX(검수!$L$2:$L$184,MATCH($C21,검수!$C$2:$C$184,0))),"") | S21: =IF(OR(R21="",J21=""),"",IF(R21=J21,"일치","불일치")) | T21: =IF(OR(Q21="",I21=""),"",IF(Q21=I21,"일치","불일치"))

Sheet 요약
A1: 검수 요약 (자동 계산)
A3: 전체 과정 수 | B3: =COUNTA(검수!$C$2:$C$184) -> 183
A4: 판정 입력 완료 | B4: =COUNTA(검수!$L$2:$L$184) -> 0
A5: 진행률 | B5: =IF(B3=0,0,B4/B3) -> 0
A7: ② 판정 | B7: 건수 | C7: 비율
A8: 맞음 | B8: =COUNTIF(검수!$L$2:$L$184,A8) -> 0 | C8: =IF($B$4=0,0,B8/$B$4) -> 0
A9: 일부 틀림 | B9: =COUNTIF(검수!$L$2:$L$184,A9) -> 0 | C9: =IF($B$4=0,0,B9/$B$4) -> 0
A10: 틀림 | B10: =COUNTIF(검수!$L$2:$L$184,A10) -> 0 | C10: =IF($B$4=0,0,B10/$B$4) -> 0
A12: ① 관련 여부 | B12: 건수
A13: 관련 | B13: =COUNTIF(검수!$K$2:$K$184,A13) -> 0
A14: 일부 관련 | B14: =COUNTIF(검수!$K$2:$K$184,A14) -> 0
A15: 무관 | B15: =COUNTIF(검수!$K$2:$K$184,A15) -> 0
A17: 분야별 | B17: 자동 연결 과정 | C17: 검수 완료 | D17: 맞음 | E17: 일치율
A18: 인사전략·인력기획 | B18: =COUNTIF(검수!$I$2:$I$184,"*"&A18&"*") -> 1 | C18: =COUNTIFS(검수!$I$2:$I$184,"*"&A18&"*",검수!$L$2:$L$184,"<>") -> 0 | D18: =COUNTIFS(검수!$I$2:$I$184,"*"&A18&"*",검수!$L$2:$L$184,"맞음") -> 0 | E18: =IF(C18=0,0,D18/C18) -> 0
A19: 조직설계·직무분석 | B19: =COUNTIF(검수!$I$2:$I$184,"*"&A19&"*") -> 1 | C19: =COUNTIFS(검수!$I$2:$I$184,"*"&A19&"*",검수!$L$2:$L$184,"<>") -> 0 | D19: =COUNTIFS(검수!$I$2:$I$184,"*"&A19&"*",검수!$L$2:$L$184,"맞음") -> 0 | E19: =IF(C19=0,0,D19/C19) -> 0
A20: 인재채용 | B20: =COUNTIF(검수!$I$2:$I$184,"*"&A20&"*") -> 20 | C20: =COUNTIFS(검수!$I$2:$I$184,"*"&A20&"*",검수!$L$2:$L$184,"<>") -> 0 | D20: =COUNTIFS(검수!$I$2:$I$184,"*"&A20&"*",검수!$L$2:$L$184,"맞음") -> 0 | E20: =IF(C20=0,0,D20/C20) -> 0
A21: 온보딩·직원경험 | B21: =COUNTIF(검수!$I$2:$I$184,"*"&A21&"*") -> 12 | C21: =COUNTIFS(검수!$I$2:$I$184,"*"&A21&"*",검수!$L$2:$L$184,"<>") -> 0 | D21: =COUNTIFS(검수!$I$2:$I$184,"*"&A21&"*",검수!$L$2:$L$184,"맞음") -> 0 | E21: =IF(C21=0,0,D21/C21) -> 0
A22: 성과평가·목표관리 | B22: =COUNTIF(검수!$I$2:$I$184,"*"&A22&"*") -> 21 | C22: =COUNTIFS(검수!$I$2:$I$184,"*"&A22&"*",검수!$L$2:$L$184,"<>") -> 0 | D22: =COUNTIFS(검수!$I$2:$I$184,"*"&A22&"*",검수!$L$2:$L$184,"맞음") -> 0 | E22: =IF(C22=0,0,D22/C22) -> 0
A23: 보상·급여·복리후생 | B23: =COUNTIF(검수!$I$2:$I$184,"*"&A23&"*") -> 2 | C23: =COUNTIFS(검수!$I$2:$I$184,"*"&A23&"*",검수!$L$2:$L$184,"<>") -> 0 | D23: =COUNTIFS(검수!$I$2:$I$184,"*"&A23&"*",검수!$L$2:$L$184,"맞음") -> 0 | E23: =IF(C23=0,0,D23/C23) -> 0
A24: 인재육성·사내교육 | B24: =COUNTIF(검수!$I$2:$I$184,"*"&A24&"*") -> 18 | C24: =COUNTIFS(검수!$I$2:$I$184,"*"&A24&"*",검수!$L$2:$L$184,"<>") -> 0 | D24: =COUNTIFS(검수!$I$2:$I$184,"*"&A24&"*",검수!$L$2:$L$184,"맞음") -> 0 | E24: =IF(C24=0,0,D24/C24) -> 0
A25: 조직문화·사내소통 | B25: =COUNTIF(검수!$I$2:$I$184,"*"&A25&"*") -> 0 | C25: =COUNTIFS(검수!$I$2:$I$184,"*"&A25&"*",검수!$L$2:$L$184,"<>") -> 0 | D25: =COUNTIFS(검수!$I$2:$I$184,"*"&A25&"*",검수!$L$2:$L$184,"맞음") -> 0 | E25: =IF(C25=0,0,D25/C25) -> 0
A26: 노사관계·노무 | B26: =COUNTIF(검수!$I$2:$I$184,"*"&A26&"*") -> 26 | C26: =COUNTIFS(검수!$I$2:$I$184,"*"&A26&"*",검수!$L$2:$L$184,"<>") -> 0 | D26: =COUNTIFS(검수!$I$2:$I$184,"*"&A26&"*",검수!$L$2:$L$184,"맞음") -> 0 | E26: =IF(C26=0,0,D26/C26) -> 0
A27: (없음) | B27: =COUNTIF(검수!$I$2:$I$184,"(없음)") -> 87 | C27: =COUNTIFS(검수!$I$2:$I$184,"(없음)",검수!$L$2:$L$184,"<>") -> 0 | D27: =COUNTIFS(검수!$I$2:$I$184,"(없음)",검수!$L$2:$L$184,"맞음") -> 0 | E27: =IF(C27=0,0,D27/C27) -> 0
A28: 일치율 = 검수 완료 중 '맞음' 비율. '(없음)'의 맞음은 '9개 분야 어디에도 안 맞음'이 맞다는 뜻.
A30: 팀원별 | B30: 배정 | C30: 완료 | D30: 진행률 | E30: 교차 배정 | F30: 교차 완료
A31: 팀원A | B31: =COUNTIF(검수!$B$2:$B$184,A31) -> 46 | C31: =COUNTIFS(검수!$B$2:$B$184,A31,검수!$L$2:$L$184,"<>") -> 0 | D31: =IF(B31=0,0,C31/B31) -> 0 | E31: =COUNTIF(교차검수!$B$2:$B$21,A31) -> 5 | F31: =COUNTIFS(교차검수!$B$2:$B$21,A31,교차검수!$J$2:$J$21,"<>") -> 0
A32: 팀원B | B32: =COUNTIF(검수!$B$2:$B$184,A32) -> 46 | C32: =COUNTIFS(검수!$B$2:$B$184,A32,검수!$L$2:$L$184,"<>") -> 0 | D32: =IF(B32=0,0,C32/B32) -> 0 | E32: =COUNTIF(교차검수!$B$2:$B$21,A32) -> 5 | F32: =COUNTIFS(교차검수!$B$2:$B$21,A32,교차검수!$J$2:$J$21,"<>") -> 0
A33: 팀원C | B33: =COUNTIF(검수!$B$2:$B$184,A33) -> 46 | C33: =COUNTIFS(검수!$B$2:$B$184,A33,검수!$L$2:$L$184,"<>") -> 0 | D33: =IF(B33=0,0,C33/B33) -> 0 | E33: =COUNTIF(교차검수!$B$2:$B$21,A33) -> 5 | F33: =COUNTIFS(교차검수!$B$2:$B$21,A33,교차검수!$J$2:$J$21,"<>") -> 0
A34: 팀원D | B34: =COUNTIF(검수!$B$2:$B$184,A34) -> 45 | C34: =COUNTIFS(검수!$B$2:$B$184,A34,검수!$L$2:$L$184,"<>") -> 0 | D34: =IF(B34=0,0,C34/B34) -> 0 | E34: =COUNTIF(교차검수!$B$2:$B$21,A34) -> 5 | F34: =COUNTIFS(교차검수!$B$2:$B$21,A34,교차검수!$J$2:$J$21,"<>") -> 0
A37: 교차검수 (② 판정 기준)
A38: 교차검수 과정 수 | B38: =COUNTA(교차검수!$C$2:$C$21) -> 20
A39: 두 사람 모두 판정 | B39: =SUMPRODUCT(((교차검수!$R$2:$R$21<>"")*(교차검수!$J$2:$J$21<>""))) -> 0
A40: 판정 일치 | B40: =SUMPRODUCT(((교차검수!$R$2:$R$21<>"")*(교차검수!$J$2:$J$21<>""))*(교차검수!$R$2:$R$21=교차검수!$J$2:$J$21)) -> 0
A41: 일치율 | B41: =IF(B39=0,0,B40/B39) -> 0
A42: 우연 일치 기대값(pe) | B42: =IF(B39=0,0,(SUMPRODUCT(((교차검수!$R$2:$R$21<>"")*(교차검수!$J$2:$J$21<>""))*(교차검수!$R$2:$R$21="맞음"))*SUMPRODUCT(((교차검수!$R$2:$R$21<>"")*(교차검수!$J$2:$J$21<>""))*(교차검수!$J$2:$J$21="맞음"))+SUMPRODUCT(((교차검수!$R$2:$R$21<>"")*(교차검수!$J$2:$J$21<>""))*(교차검수!$R$2:$R$21="일부 틀림"))*SUMPRODUCT(((교차검수!$R$2:$R$21<>"")*(교차검수!$J$2:$J$21<>""))*(교차검수!$J$2:$J$21="일부 틀림"))+SUMPRODUCT(((교차검수!$R$2:$R$21<>"")*(교차검수!$J$2:$J$21<>""))*(교차검수!$R$2:$R$21="틀림"))*SUMPRODUCT(((교차검수!$R$2:$R$21<>"")*(교차검수!$J$2:$J$21<>""))*(교차검수!$J$2:$J$21="틀림")))/B39^2) -> 0
A43: 카파 계수(κ) | B43: =IF(OR(B39=0,B42=1),"-",(B41-B42)/(1-B42)) -> -
A44: ① 관련 여부 일치율 | B44: =IF(SUMPRODUCT((교차검수!$Q$2:$Q$21<>"")*(교차검수!$I$2:$I$21<>""))=0,0,SUMPRODUCT((교차검수!$Q$2:$Q$21<>"")*(교차검수!$I$2:$I$21<>"")*(교차검수!$Q$2:$Q$21=교차검수!$I$2:$I$21))/SUMPRODUCT((교차검수!$Q$2:$Q$21<>"")*(교차검수!$I$2:$I$21<>""))) -> 0
A45: 카파 해석(참고): 0.6 이상이면 판정 기준이 대체로 일치, 0.4 미만이면 기준을 다시 맞추는 회의가 필요합니다.

Sheet 분야 기준
A1: 분야 ID | B1: 분야 이름 | C1: 연결 키워드(과정명에 포함되면 연결)
A2: DOM_01 | B2: 인사전략·인력기획 | C2: 인력계획, 인력 계획, 인력운영, 정원, 인건비, 인사기획, 인사전략, 인력관리
A3: DOM_02 | B3: 조직설계·직무분석 | C3: 직무분석, 직무기술서, 조직설계, 직무관리, 직무평가, 직무중심, 직무급
A4: DOM_03 | B4: 인재채용 | C4: 채용, 면접, 선발, 리크루팅, 헤드헌팅
A5: DOM_04 | B5: 온보딩·직원경험 | C5: 온보딩, 신입사원, 신규입사, 리텐션
A6: DOM_05 | B6: 성과평가·목표관리 | C6: 성과관리, 성과평가, 인사평가, 평가제도, 평가체계, kpi, okr, mbo, 목표관리
A7: DOM_06 | B7: 보상·급여·복리후생 | C7: 보상, 연봉제, 급여, 임금, 4대보험, 연말정산, 원천징수, 퇴직금, 복리후생, 인센티브
A8: DOM_07 | B8: 인재육성·사내교육 | C8: hrd, 교육담당, 교육과정, 사내강사, 교수설계, addie, 인재육성, 교육기획
A9: DOM_08 | B9: 조직문화·사내소통 | C9: 조직문화, 조직활성화, 조직개발, 몰입, 핵심가치, 팀빌딩, 조직진단
A10: DOM_09 | B10: 노사관계·노무 | C10: 노무, 노동법, 근로기준법, 노사, 취업규칙, 징계, 해고, 노동조합, 근로계약
